Workbook

Sheet Nasıl kullanılır
A1: Bitkiye göre toprak önerisi — taslak (kontrol için)
A3: Bu dosya ne yapar?
A4: Her toprağa ve her bitkiye aynı 5 ölçütle bir profil verilir. Bitkiye özel toprak varsa o önerilir; yoksa profili en yakın toprak 'uyum puanı' ile seçilir.
A5: Eksik kalan özellik için katkı önerilir (drenaj → perlit, pH → asidik torf, su tutma → vermikülit, besin → solucan gübresi).
A7: Neyi düzenlemelisiniz?
A8: • Sarı hücreler girdidir: 'Topraklar' sayfasında D–H ve J sütunları, 'Bitkiler' sayfasında D–I sütunları.
A9: • Mavi hücreler formüldür, dokunmayın: 'Bitkiler' J–N sütunları ve 'Uyum' sayfası kendiliğinden hesaplanır.
A10: • Ağırlıklar 'Ayarlar' sayfasındadır (pH ve drenaj en önemli kabul edildi).
A12: Ölçekler
A13: pH: 1 = Asidik (4,5–5,5) · 2 = Hafif asidik (5,5–6,5) · 3 = Nötr (6,5–7,5) · 4 = Kireçli (7,5+)
A14: Drenaj (su süzme): 1 = Orta · 2 = Yüksek · 3 = Çok yüksek
A15: Su tutma: 1 = Düşük · 2 = Orta · 3 = Yüksek
... A24: • Yeni toprak eklediğinizde bu dosyayı güncellemeniz gerekmez: ikas'ta ürüne etiket eklemeniz yeterli (README'de anlatıldı).

Sheet Ayarlar
A1: Ölçüt | B1: Ağırlık | C1: Açıklama
A2: pH | B2: 3 | C2: En önemli: yanlış pH bitkinin besin almasını engeller
A3: Drenaj | B3: 2 | C3: Kök çürümesi riskini belirler
A4: Su tutma | B4: 2
A5: Besin | B5: 1 | C5: Gübreyle kolayca tamamlanabilir
A6: Yapı | B6: 1 | C6: Farklıysa 1 puan fark sayılır
A7: Bölen | B7: 12 | C7: Toplam fark bu sayıya bölünür; küçüldükçe puanlar sertleşir
A9: Uyum = 1 − (pH_ağ·|ΔpH| + Drenaj_ağ·|ΔDrenaj| + Su_ağ·|ΔSu| + Besin_ağ·|ΔBesin| + Yapı_ağ·(yapı farklıysa 1)) / Bölen

Sheet Topraklar
A1: Ürün adresi (slug) | B1: Ürün adı | C1: Tür | D1: pH | E1: Drenaj | F1: Su tutma | G1: Besin | H1: Yapı | I1: Not | J1: Sadece özel | K1: Grup | L1: Genel amaçlı
A2: hg-monstera-deve-tabani-topragi | B2: HG Monstera (Deve Tabanı) Toprağı | C2: Toprak | D2: 2 | E2: 3 | F2: 2 | G2: 2 | H2: Havalı | J2: Hayır | K2: Salon | L2: Hayır
A3: hg-salon-sarmasigi-topragi | B3: HG Salon Sarmaşığı Toprağı | C3: Toprak | D3: 2 | E3: 2 | F3: 2 | G3: 2 | H3: Havalı | J3: Hayır | K3: Salon | L3: Hayır
A4: pasa-kilici-sansevieria-topragi | B4: HG Paşa Kılıcı (Sansevieria) Toprağı | C4: Toprak | D4: 3 | E4: 3 | F4: 1 | G4: 1 | H4: Kumlu | J4: Hayır | K4: Salon | L4: Hayır
A5: kaucuk-agaci-topragi | B5: HG Kauçuk Ağacı Toprağı | C5: Toprak | D5: 2 | E5: 2 | F5: 2 | G5: 2 | H5: Dengeli | J5: Hayır | K5: Salon | L5: Hayır
A6: hg-benjamin-saksi-topragi | B6: HG Benjamin Saksı Toprağı | C6: Toprak | D6: 2 | E6: 2 | F6: 2 | G6: 2 | H6: Dengeli | J6: Hayır | K6: Salon | L6: Hayır
A7: hg-difenbahya-saksi-topragi | B7: HG Difenbahya Saksı Toprağı | C7: Toprak | D7: 2 | E7: 2 | F7: 2 | G7: 2 | H7: Havalı | J7: Hayır | K7: Salon | L7: Hayır
A8: baris-cicegi-spathiphyllum-topragi | B8: Barış Çiçeği (Spathiphyllum) Toprağı | C8: Toprak | D8: 2 | E8: 2 | F8: 3 | G8: 2 | H8: Havalı | J8: Hayır | K8: Salon | L8: Hayır
A9: hg-antoryum-cicegi-topragi | B9: HG Antoryum Çiçeği Toprağı | C9: Toprak | D9: 2 | E9: 3 | F9: 2 | G9: 2 | H9: Havalı | J9: Hayır | K9: Salon | L9: Hayır
A10: hg-dua-cicegi-saksi-topragi | B10: HG Dua Çiçeği Saksı Toprağı | C10: Toprak | D10: 2 | E10: 2 | F10: 3 | G10: 2 | H10: Havalı | J10: Hayır | K10: Salon | L10: Hayır
A11: hg-fil-kulagi-topragi | B11: HG Fil Kulağı Toprağı | C11: Toprak | D11: 2 | E11: 2 | F11: 3 | G11: 3 | H11: Havalı | J11: Hayır | K11: Salon | L11: Hayır
A12: areka-palmiyesi-topragi | B12: HG Areka Palmiyesi Toprağı | C12: Toprak | D12: 2 | E12: 2 | F12: 2 | G12: 2 | H12: Havalı | J12: Hayır | K12: Salon | L12: Hayır
A13: hg-seflera-schefflera-topragi | B13: HG Şeflera (Schefflera) Toprağı | C13: Toprak | D13: 2 | E13: 2 | F13: 2 | G13: 2 | H13: Dengeli | J13: Hayır | K13: Salon | L13: Hayır
... A17: kaktus-ve-sukulent-topragi | B17: HG Kaktüs ve Sukulent Toprağı | C17: Toprak | D17: 3 | E17: 3 | F17: 1 | G17: 1 | H17: Kumlu | J17: Hayır | K17: Sukulent | L17: Evet
A18: gartengold-orkide-topragi | B18: Gartengold Orkide Toprağı 2.5 Lt | C18: Toprak | D18: 2 | E18: 3 | F18: 1 | G18: 1 | H18: Havalı | I18: Kabuk bazlı | J18: Hayır | K18: Salon | L18: Hayır
A19: hg-menekse-topragi | B19: HG Menekşe Toprağı | C19: Toprak | D19: 2 | E19: 2 | F19: 2 | G19: 2 | H19: Havalı | J19: Hayır | K19: Salon | L19: Hayır
A20: hg-begonvil-topragi | B20: HG Begonvil Toprağı | C20: Toprak | D20: 2 | E20: 3 | F20: 1 | G20: 2 | H20: Kumlu | J20: Hayır | K20: Çiçek | L20: Hayır
A21: sardunya-pelargonium-cicegi-topragi | B21: HG Sardunya (Pelargonium) Çiçeği Toprağı | C21: Toprak | D21: 3 | E21: 3 | F21: 1 | G21: 2 | H21: Kumlu | J21: Hayır | K21: Çiçek | L21: Hayır
A22: hg-starlice-cennet-kusu-topragi | B22: HG Starliçe & Cennet Kuşu Toprağı | C22: Toprak | D22: 2 | E22: 2 | F22: 2 | G22: 3 | H22: Dengeli | J22: Hayır | K22: Salon | L22: Hayır
A23: hg-bonsai-saksi-topragi | B23: HG Bonsai Saksı Toprağı | C23: Toprak | D23: 2 | E23: 3 | F23: 1 | G23: 1 | H23: Kumlu | J23: Hayır | K23: Salon | L23: Hayır
A24: hg-para-agaci-saksi-topragi | B24: HG Para Ağacı Saksı Toprağı | C24: Toprak | D24: 2 | E24: 3 | F24: 1 | G24: 2 | H24: Kumlu | I24: Para ağacı = Pachira mı Crassula mı? Kontrol edin | J24: Hayır | K24: Salon | L24: Hayır
A25: salon-bitkilerine-ozel-toprak-karisimi | B25: HG Salon Bitkilerine Özel Toprak Karışımı | C25: Toprak | D25: 2 | E25: 2 | F25: 2 | G25: 2 | H25: Dengeli | J25: Hayır | K25: Salon | L25: Evet
A26: hg-cicek-topragi | B26: HG Çiçek Toprağı | C26: Toprak | D26: 2 | E26: 2 | F26: 2 | G26: 3 | H26: Dengeli | J26: Hayır | K26: Çiçek | L26: Evet
A27: hg-gul-topragi-gullere-ozel-toprak-karisimi | B27: HG Gül Toprağı | C27: Toprak | D27: 3 | E27: 2 | F27: 2 | G27: 3 | H27: Dengeli | J27: Hayır | K27: Çiçek | L27: Hayır
A28: ortanca-bogurtlen-acelya-topragi | B28: HG Asit Seven Bitkiler İçin Özel Karışım Organik Torf | C28: Toprak | D28: 1 | E28: 2 | F28: 2 | G28: 2 | H28: Dengeli | I28: Ortanca, böğürtlen, açelya | J28: Hayır | K28: Asit seven | L28: Evet
A29: yaban-mersini-ve-ortanca-topragi | B29: Yaban Mersini ve Ortanca Toprağı | C29: Toprak | D29: 1 | E29: 2 | F29: 2 | G29: 2 | H29: Dengeli | J29: Hayır | K29: Asit seven | L29: Hayır
A30: aronya-bitkisi-topragi-ozel-asidik-torf-karisimi | B30: HG Aronya Toprağı | C30: Toprak | D30: 1 | E30: 2 | F30: 2 | G30: 2 | H30: Dengeli | J30: Hayır | K30: Asit seven | L30: Hayır
A31: limon-agaci-topragi-ozel-organik-karisim | B31: Limon Ağacı Toprağı - Özel Organik Karışım | C31: Toprak | D31: 2 | E31: 3 | F31: 2 | G31: 3 | H31: Dengeli | J31: Hayır | K31: Meyve | L31: Hayır
A32: hg-narenciye-topragi | B32: HG Narenciye Toprağı | C32: Toprak | D32: 2 | E32: 3 | F32: 2 | G32: 3 | H32: Dengeli | J32: Hayır | K32: Meyve | L32: Hayır
A33: hg-kumkuat-kamkat-topragi-ozel-karisim | B33: HG Kumkuat (Kamkat) Toprağı | C33: Toprak | D33: 2 | E33: 3 | F33: 2 | G33: 3 | H33: Dengeli | J33: Hayır | K33: Meyve | L33: Hayır
A34: hg-avokado-topragi-ozel-karisim | B34: HG Avokado Toprağı | C34: Toprak | D34: 2 | E34: 3 | F34: 2 | G34: 2 | H34: Havalı | J34: Hayır | K34: Meyve | L34: Hayır
A35: trabzon-hurmasi-cennet-hurmasi-topragi | B35: HG Trabzon Hurması Toprağı | C35: Toprak | D35: 3 | E35: 2 | F35: 2 | G35: 2 | H35: Dengeli | J35: Hayır | K35: Meyve | L35: Hayır
A36: hg-cilek-topragi | B36: HG Çilek Toprağı Özel Karışım | C36: Toprak | D36: 2 | E36: 2 | F36: 2 | G36: 3 | H36: Dengeli | J36: Hayır | K36: Meyve | L36: Hayır
A37: solucan-gubreli-sebze-topragi | B37: HG Organik Sebze Yetiştirme Toprağı | C37: Toprak | D37: 3 | E37: 2 | F37: 2 | G37: 3 | H37: Dengeli | J37: Hayır | K37: Sebze | L37: Evet
A38: hg-bol-verimli-sebze-topragi | B38: HG Premium Sebze Yetiştirme Toprağı | C38: Toprak | D38: 3 | E38: 2 | F38: 2 | G38: 3 | H38: Dengeli | J38: Hayır | K38: Sebze | L38: Evet
A39: hg-aromatik-bitkiler-icin-saksi-topragi | B39: HG Aromatik Bitkiler İçin Saksı Toprağı | C39: Toprak | D39: 3 | E39: 3 | F39: 1 | G39: 2 | H39: Kumlu | J39: Hayır | K39: Aromatik | L39: Hayır
A40: hg-fide-topragi | B40: Fide Toprağı | C40: Toprak | D40: 2 | E40: 2 | F40: 2 | G40: 1 | H40: Dengeli | I40: İnce yapılı, çimlendirme | J40: Hayır | K40: Sebze | L40: Hayır
A41: hg-premium-fide-topragi | B41: Premium Fide Toprağı | C41: Toprak | D41: 2 | E41: 2 | F41: 2 | G41: 1 | H41: Dengeli | J41: Hayır | K41: Sebze | L41: Hayır
A42: fide-sasirtma-topragi | B42: Profesyonel Fide Şaşırtma Toprağı | C42: Toprak | D42: 2 | E42: 2 | F42: 2 | G42: 2 | H42: Dengeli | J42: Hayır | K42: Sebze | L42: Hayır
A43: lotus-nilufer-cicegi-topragi | B43: HG Lotus Nilüfer Çiçeği Toprağı | C43: Toprak | D43: 3 | E43: 1 | F43: 3 | G43: 3 | H43: Dengeli | I43: Su bitkisi; sadece nilüfer/lotus için | J43: Evet | L43: Hayır
...

Sheet Bitkiler
A1: Bitki | B1: Eş anlamlılar (arama için) | C1: Grup | D1: pH | E1: Drenaj | F1: Su tutma | G1: Besin | H1: Yapı | I1: Özel toprak (slug) | J1: Özel toprak adı | K1: Profile en yakın toprak | L1: Uyum | M1: Önerilecek toprak | N1: Ek öneri
A2: Monstera | B2: deve tabanı | C2: Salon | D2: 2 | E2: 3 | F2: 2 | G2: 2 | H2: Havalı | I2: hg-monstera-deve-tabani-topragi | J2: =IF(I2="","",IFERROR(INDEX(Topraklar!$B$2:$B$55,MATCH(I2,Topraklar!$A$2:$A$55,0)),"⚠ slug bulunamadı")) | K2: =INDEX(Uyum!$B$2:$AY$2,MATCH(MAX(Uyum!$B$3:$AY$3),Uyum!$B$3:$AY$3,0)) | L2: =MIN(1,MAX(Uyum!$B$3:$AY$3)) | M2: =IF(I2<>"",J2,K2) | N2: =IFERROR(TRIM(IF(E2>INDEX(Topraklar!$E$2:$E$55,MATCH(IF(I2<>"",I2,INDEX(Uyum!$B$1:$AY$1,MATCH(MAX(Uyum!$B$3:$AY$3),Uyum!$B$3:$AY$3,0))),Topraklar!$A$2:$A$55,0)),"Perlit karıştırın. ","")&IF(D2<INDEX(Topraklar!$D$2:$D$55,MATCH(IF(I2<>"",I2,INDEX(Uyum!$B$1:$AY$1,MATCH(MAX(Uyum!$B$3:$AY$3),Uyum!$B$3:$AY$3,0))),Topraklar!$A$2:$A$55,0)),"Asidik torf karıştırın. ","")&IF(F2>INDEX(Topraklar!$F$2:$F$55,MATCH(IF(I2<>"",I2,INDEX(Uyum!$B$1:$AY$1,MATCH(MAX(Uyum!$B$3:$AY$3),Uyum!$B$3:$AY$3,0))),Topraklar!$A$2:$A$55,0)),"Vermikülit karıştırın. ","")&IF(G2>INDEX(Topraklar!$G$2:$G$55,MATCH(IF(I2<>"",I2,INDEX(Uyum!$B$1:$AY$1,MATCH(MAX(Uyum!$B$3:$AY$3),Uyum!$B$3:$AY$3,0))),Topraklar!$A$2:$A$55,0)),"Solucan gübresi ekleyin.","")),"")
A3: Philodendron | B3: filodendron | C3: Salon | D3: 2 | E3: 3 | F3: 2 | G3: 2 | H3: Havalı | J3: =IF(I3="","",IFERROR(INDEX(Topraklar!$B$2:$B$55,MATCH(I3,Topraklar!$A$2:$A$55,0)),"⚠ slug bulunamadı")) | K3: =INDEX(Uyum!$B$2:$AY$2,MATCH(MAX(Uyum!$B$4:$AY$4),Uyum!$B$4:$AY$4,0)) | L3: =MIN(1,MAX(Uyum!$B$4:$AY$4)) | M3: =IF(I3<>"",J3,K3) | N3: =IFERROR(TRIM(IF(E3>INDEX(Topraklar!$E$2:$E$55,MATCH(IF(I3<>"",I3,INDEX(Uyum!$B$1:$AY$1,MATCH(MAX(Uyum!$B$4:$AY$4),Uyum!$B$4:$AY$4,0))),Topraklar!$A$2:$A$55,0)),"Perlit karıştırın. ","")&IF(D3<INDEX(Topraklar!$D$2:$D$55,MATCH(IF(I3<>"",I3,INDEX(Uyum!$B$1:$AY$1,MATCH(MAX(Uyum!$B$4:$AY$4),Uyum!$B$4:$AY$4,0))),Topraklar!$A$2:$A$55,0)),"Asidik torf karıştırın. ","")&IF(F3>INDEX(Topraklar!$F$2:$F$55,MATCH(IF(I3<>"",I3,INDEX(Uyum!$B$1:$AY$1,MATCH(MAX(Uyum!$B$4:$AY$4),Uyum!$B$4:$AY$4,0))),Topraklar!$A$2:$A$55,0)),"Vermikülit karıştırın. ","")&IF(G3>INDEX(Topraklar!$G$2:$G$55,MATCH(IF(I3<>"",I3,INDEX(Uyum!$B$1:$AY$1,MATCH(MAX(Uyum!$B$4:$AY$4),Uyum!$B$4:$AY$4,0))),Topraklar!$A$2:$A$55,0)),"Solucan gübresi ekleyin.","")),"")
A4: Salon sarmaşığı | B4: pothos, potos, epipremnum | C4: Salon | D4: 2 | E4: 2 | F4: 2 | G4: 2 | H4: Havalı | I4: hg-salon-sarmasigi-topragi | J4: =IF(I4="","",IFERROR(INDEX(Topraklar!$B$2:$B$55,MATCH(I4,Topraklar!$A$2:$A$55,0)),"⚠ slug bulunamadı")) | K4: =INDEX(Uyum!$B$2:$AY$2,MATCH(MAX(Uyum!$B$5:$AY$5),Uyum!$B$5:$AY$5,0)) | L4: =MIN(1,MAX(Uyum!$B$5:$AY$5)) | M4: =IF(I4<>"",J4,K4) | N4: =IFERROR(TRIM(IF(E4>INDEX(Topraklar!$E$2:$E$55,MATCH(IF(I4<>"",I4,INDEX(Uyum!$B$1:$AY$1,MATCH(MAX(Uyum!$B$5:$AY$5),Uyum!$B$5:$AY$5,0))),Topraklar!$A$2:$A$55,0)),"Perlit karıştırın. ","")&IF(D4<INDEX(Topraklar!$D$2:$D$55,MATCH(IF(I4<>"",I4,INDEX(Uyum!$B$1:$AY$1,MATCH(MAX(Uyum!$B$5:$AY$5),Uyum!$B$5:$AY$5,0))),Topraklar!$A$2:$A$55,0)),"Asidik torf karıştırın. ","")&IF(F4>INDEX(Topraklar!$F$2:$F$55,MATCH(IF(I4<>"",I4,INDEX(Uyum!$B$1:$AY$1,MATCH(MAX(Uyum!$B$5:$AY$5),Uyum!$B$5:$AY$5,0))),Topraklar!$A$2:$A$55,0)),"Vermikülit karıştırın. ","")&IF(G4>INDEX(Topraklar!$G$2:$G$55,MATCH(IF(I4<>"",I4,INDEX(Uyum!$B$1:$AY$1,MATCH(MAX(Uyum!$B$5:$AY$5),Uyum!$B$5:$AY$5,0))),Topraklar!$A$2:$A$55,0)),"Solucan gübresi ekleyin.","")),"")
A5: Zamioculcas | B5: zz bitkisi, zamia | C5: Salon | D5: 3 | E5: 3 | F5: 1 | G5: 1 | H5: Kumlu | J5: =IF(I5="","",IFERROR(INDEX(Topraklar!$B$2:$B$55,MATCH(I5,Topraklar!$A$2:$A$55,0)),"⚠ slug bulunamadı")) | K5: =INDEX(Uyum!$B$2:$AY$2,MATCH(MAX(Uyum!$B$6:$AY$6),Uyum!$B$6:$AY$6,0)) | L5: =MIN(1,MAX(Uyum!$B$6:$AY$6)) | M5: =IF(I5<>"",J5,K5) | N5: =IFERROR(TRIM(IF(E5>INDEX(Topraklar!$E$2:$E$55,MATCH(IF(I5<>"",I5,INDEX(Uyum!$B$1:$AY$1,MATCH(MAX(Uyum!$B$6:$AY$6),Uyum!$B$6:$AY$6,0))),Topraklar!$A$2:$A$55,0)),"Perlit karıştırın. ","")&IF(D5<INDEX(Topraklar!$D$2:$D$55,MATCH(IF(I5<>"",I5,INDEX(Uyum!$B$1:$AY$1,MATCH(MAX(Uyum!$B$6:$AY$6),Uyum!$B$6:$AY$6,0))),Topraklar!$A$2:$A$55,0)),"Asidik torf karıştırın. ","")&IF(F5>INDEX(Topraklar!$F$2:$F$55,MATCH(IF(I5<>"",I5,INDEX(Uyum!$B$1:$AY$1,MATCH(MAX(Uyum!$B$6:$AY$6),Uyum!$B$6:$AY$6,0))),Topraklar!$A$2:$A$55,0)),"Vermikülit karıştırın. ","")&IF(G5>INDEX(Topraklar!$G$2:$G$55,MATCH(IF(I5<>"",I5,INDEX(Uyum!$B$1:$AY$1,MATCH(MAX(Uyum!$B$6:$AY$6),Uyum!$B$6:$AY$6,0))),Topraklar!$A$2:$A$55,0)),"Solucan gübresi ekleyin.","")),"")
A6: Paşa kılıcı | B6: sansevieria, kaynana dili | C6: Salon | D6: 3 | E6: 3 | F6: 1 | G6: 1 | H6: Kumlu | I6: pasa-kilici-sansevieria-topragi | J6: =IF(I6="","",IFERROR(INDEX(Topraklar!$B$2:$B$55,MATCH(I6,Topraklar!$A$2:$A$55,0)),"⚠ slug bulunamadı")) | K6: =INDEX(Uyum!$B$2:$AY$2,MATCH(MAX(Uyum!$B$7:$AY$7),Uyum!$B$7:$AY$7,0)) | L6: =MIN(1,MAX(Uyum!$B$7:$AY$7)) | M6: =IF(I6<>"",J6,K6) | N6: =IFERROR(TRIM(IF(E6>INDEX(Topraklar!$E$2:$E$55,MATCH(IF(I6<>"",I6,INDEX(Uyum!$B$1:$AY$1,MATCH(MAX(Uyum!$B$7:$AY$7),Uyum!$B$7:$AY$7,0))),Topraklar!$A$2:$A$55,0)),"Perlit karıştırın. ","")&IF(D6<INDEX(Topraklar!$D$2:$D$55,MATCH(IF(I6<>"",I6,INDEX(Uyum!$B$1:$AY$1,MATCH(MAX(Uyum!$B$7:$AY$7),Uyum!$B$7:$AY$7,0))),Topraklar!$A$2:$A$55,0)),"Asidik torf karıştırın. ","")&IF(F6>INDEX(Topraklar!$F$2:$F$55,MATCH(IF(I6<>"",I6,INDEX(Uyum!$B$1:$AY$1,MATCH(MAX(Uyum!$B$7:$AY$7),Uyum!$B$7:$AY$7,0))),Topraklar!$A$2:$A$55,0)),"Vermikülit karıştırın. ","")&IF(G6>INDEX(Topraklar!$G$2:$G$55,MATCH(IF(I6<>"",I6,INDEX(Uyum!$B$1:$AY$1,MATCH(MAX(Uyum!$B$7:$AY$7),Uyum!$B$7:$AY$7,0))),Topraklar!$A$2:$A$55,0)),"Solucan gübresi ekleyin.","")),"")
A7: Kauçuk | B7: kauçuk ağacı, ficus elastica | C7: Salon | D7: 2 | E7: 2 | F7: 2 | G7: 2 | H7: Dengeli | I7: kaucuk-agaci-topragi | J7: =IF(I7="","",IFERROR(INDEX(Topraklar!$B$2:$B$55,MATCH(I7,Topraklar!$A$2:$A$55,0)),"⚠ slug bulunamadı")) | K7: =INDEX(Uyum!$B$2:$AY$2,MATCH(MAX(Uyum!$B$8:$AY$8),Uyum!$B$8:$AY$8,0)) | L7: =MIN(1,MAX(Uyum!$B$8:$AY$8)) | M7: =IF(I7<>"",J7,K7) | N7: =IFERROR(TRIM(IF(E7>INDEX(Topraklar!$E$2:$E$55,MATCH(IF(I7<>"",I7,INDEX(Uyum!$B$1:$AY$1,MATCH(MAX(Uyum!$B$8:$AY$8),Uyum!$B$8:$AY$8,0))),Topraklar!$A$2:$A$55,0)),"Perlit karıştırın. ","")&IF(D7<INDEX(Topraklar!$D$2:$D$55,MATCH(IF(I7<>"",I7,INDEX(Uyum!$B$1:$AY$1,MATCH(MAX(Uyum!$B$8:$AY$8),Uyum!$B$8:$AY$8,0))),Topraklar!$A$2:$A$55,0)),"Asidik torf karıştırın. ","")&IF(F7>INDEX(Topraklar!$F$2:$F$55,MATCH(IF(I7<>"",I7,INDEX(Uyum!$B$1:$AY$1,MATCH(MAX(Uyum!$B$8:$AY$8),Uyum!$B$8:$AY$8,0))),Topraklar!$A$2:$A$55,0)),"Vermikülit karıştırın. ","")&IF(G7>INDEX(Topraklar!$G$2:$G$55,MATCH(IF(I7<>"",I7,INDEX(Uyum!$B$1:$AY$1,MATCH(MAX(Uyum!$B$8:$AY$8),Uyum!$B$8:$AY$8,0))),Topraklar!$A$2:$A$55,0)),"Solucan gübresi ekleyin.","")),"")
A8: Benjamin | B8: ficus benjamina | C8: Salon | D8: 2 | E8: 2 | F8: 2 | G8: 2 | H8: Dengeli | I8: hg-benjamin-saksi-topragi | J8: =IF(I8="","",IFERROR(INDEX(Topraklar!$B$2:$B$55,MATCH(I8,Topraklar!$A$2:$A$55,0)),"⚠ slug bulunamadı")) | K8: =INDEX(Uyum!$B$2:$AY$2,MATCH(MAX(Uyum!$B$9:$AY$9),Uyum!$B$9:$AY$9,0)) | L8: =MIN(1,MAX(Uyum!$B$9:$AY$9)) | M8: =IF(I8<>"",J8,K8) | N8: =IFERROR(TRIM(IF(E8>INDEX(Topraklar!$E$2:$E$55,MATCH(IF(I8<>"",I8,INDEX(Uyum!$B$1:$AY$1,MATCH(MAX(Uyum!$B$9:$AY$9),Uyum!$B$9:$AY$9,0))),Topraklar!$A$2:$A$55,0)),"Perlit karıştırın. ","")&IF(D8<INDEX(Topraklar!$D$2:$D$55,MATCH(IF(I8<>"",I8,INDEX(Uyum!$B$1:$AY$1,MATCH(MAX(Uyum!$B$9:$AY$9),Uyum!$B$9:$AY$9,0))),Topraklar!$A$2:$A$55,0)),"Asidik torf karıştırın. ","")&IF(F8>INDEX(Topraklar!$F$2:$F$55,MATCH(IF(I8<>"",I8,INDEX(Uyum!$B$1:$AY$1,MATCH(MAX(Uyum!$B$9:$AY$9),Uyum!$B$9:$AY$9,0))),Topraklar!$A$2:$A$55,0)),"Vermikülit karıştırın. ","")&IF(G8>INDEX(Topraklar!$G$2:$G$55,MATCH(IF(I8<>"",I8,INDEX(Uyum!$B$1:$AY$1,MATCH(MAX(Uyum!$B$9:$AY$9),Uyum!$B$9:$AY$9,0))),Topraklar!$A$2:$A$55,0)),"Solucan gübresi ekleyin.","")),"")
A9: Keman yapraklı incir | B9: ficus lyrata | C9: Salon | D9: 2 | E9: 2 | F9: 2 | G9: 2 | H9: Dengeli | J9: =IF(I9="","",IFERROR(INDEX(Topraklar!$B$2:$B$55,MATCH(I9,Topraklar!$A$2:$A$55,0)),"⚠ slug bulunamadı")) | K9: =INDEX(Uyum!$B$2:$AY$2,MATCH(MAX(Uyum!$B$10:$AY$10),Uyum!$B$10:$AY$10,0)) | L9: =MIN(1,MAX(Uyum!$B$10:$AY$10)) | M9: =IF(I9<>"",J9,K9) | N9: =IFERROR(TRIM(IF(E9>INDEX(Topraklar!$E$2:$E$55,MATCH(IF(I9<>"",I9,INDEX(Uyum!$B$1:$AY$1,MATCH(MAX(Uyum!$B$10:$AY$10),Uyum!$B$10:$AY$10,0))),Topraklar!$A$2:$A$55,0)),"Perlit karıştırın. ","")&IF(D9<INDEX(Topraklar!$D$2:$D$55,MATCH(IF(I9<>"",I9,INDEX(Uyum!$B$1:$AY$1,MATCH(MAX(Uyum!$B$10:$AY$10),Uyum!$B$10:$AY$10,0))),Topraklar!$A$2:$A$55,0)),"Asidik torf karıştırın. ","")&IF(F9>INDEX(Topraklar!$F$2:$F$55,MATCH(IF(I9<>"",I9,INDEX(Uyum!$B$1:$AY$1,MATCH(MAX(Uyum!$B$10:$AY$10),Uyum!$B$10:$AY$10,0))),Topraklar!$A$2:$A$55,0)),"Vermikülit karıştırın. ","")&IF(G9>INDEX(Topraklar!$G$2:$G$55,MATCH(IF(I9<>"",I9,INDEX(Uyum!$B$1:$AY$1,MATCH(MAX(Uyum!$B$10:$AY$10),Uyum!$B$10:$AY$10,0))),Topraklar!$A$2:$A$55,0)),"Solucan gübresi ekleyin.","")),"")
A10: Difenbahya | B10: dieffenbachia | C10: Salon | D10: 2 | E10: 2 | F10: 2 | G10: 2 | H10: Havalı | I10: hg-difenbahya-saksi-topragi | J10: =IF(I10="","",IFERROR(INDEX(Topraklar!$B$2:$B$55,MATCH(I10,Topraklar!$A$2:$A$55,0)),"⚠ slug bulunamadı")) | K10: =INDEX(Uyum!$B$2:$AY$2,MATCH(MAX(Uyum!$B$11:$AY$11),Uyum!$B$11:$AY$11,0)) | L10: =MIN(1,MAX(Uyum!$B$11:$AY$11)) | M10: =IF(I10<>"",J10,K10) | N10: =IFERROR(TRIM(IF(E10>INDEX(Topraklar!$E$2:$E$55,MATCH(IF(I10<>"",I10,INDEX(Uyum!$B$1:$AY$1,MATCH(MAX(Uyum!$B$11:$AY$11),Uyum!$B$11:$AY$11,0))),Topraklar!$A$2:$A$55,0)),"Perlit karıştırın. ","")&IF(D10<INDEX(Topraklar!$D$2:$D$55,MATCH(IF(I10<>"",I10,INDEX(Uyum!$B$1:$AY$1,MATCH(MAX(Uyum!$B$11:$AY$11),Uyum!$B$11:$AY$11,0))),Topraklar!$A$2:$A$55,0)),"Asidik torf karıştırın. ","")&IF(F10>INDEX(Topraklar!$F$2:$F$55,MATCH(IF(I10<>"",I10,INDEX(Uyum!$B$1:$AY$1,MATCH(MAX(Uyum!$B$11:$AY$11),Uyum!$B$11:$AY$11,0))),Topraklar!$A$2:$A$55,0)),"Vermikülit karıştırın. ","")&IF(G10>INDEX(Topraklar!$G$2:$G$55,MATCH(IF(I10<>"",I10,INDEX(Uyum!$B$1:$AY$1,MATCH(MAX(Uyum!$B$11:$AY$11),Uyum!$B$11:$AY$11,0))),Topraklar!$A$2:$A$55,0)),"Solucan gübresi ekleyin.","")),"")
A11: Barış çiçeği | B11: spathiphyllum, spatifilyum | C11: Salon | D11: 2 | E11: 2 | F11: 3 | G11: 2 | H11: Havalı | I11: baris-cicegi-spathiphyllum-topragi | J11: =IF(I11="","",IFERROR(INDEX(Topraklar!$B$2:$B$55,MATCH(I11,Topraklar!$A$2:$A$55,0)),"⚠ slug bulunamadı")) | K11: =INDEX(Uyum!$B$2:$AY$2,MATCH(MAX(Uyum!$B$12:$AY$12),Uyum!$B$12:$AY$12,0)) | L11: =MIN(1,MAX(Uyum!$B$12:$AY$12)) | M11: =IF(I11<>"",J11,K11) | N11: =IFERROR(TRIM(IF(E11>INDEX(Topraklar!$E$2:$E$55,MATCH(IF(I11<>"",I11,INDEX(Uyum!$B$1:$AY$1,MATCH(MAX(Uyum!$B$12:$AY$12),Uyum!$B$12:$AY$12,0))),Topraklar!$A$2:$A$55,0)),"Perlit karıştırın. ","")&IF(D11<INDEX(Topraklar!$D$2:$D$55,MATCH(IF(I11<>"",I11,INDEX(Uyum!$B$1:$AY$1,MATCH(MAX(Uyum!$B$12:$AY$12),Uyum!$B$12:$AY$12,0))),Topraklar!$A$2:$A$55,0)),"Asidik torf karıştırın. ","")&IF(F11>INDEX(Topraklar!$F$2:$F$55,MATCH(IF(I11<>"",I11,INDEX(Uyum!$B$1:$AY$1,MATCH(MAX(Uyum!$B$12:$AY$12),Uyum!$B$12:$AY$12,0))),Topraklar!$A$2:$A$55,0)),"Vermikülit karıştırın. ","")&IF(G11>INDEX(Topraklar!$G$2:$G$55,MATCH(IF(I11<>"",I11,INDEX(Uyum!$B$1:$AY$1,MATCH(MAX(Uyum!$B$12:$AY$12),Uyum!$B$12:$AY$12,0))),Topraklar!$A$2:$A$55,0)),"Solucan gübresi ekleyin.","")),"")
A12: Antoryum | B12: anthurium | C12: Salon | D12: 2 | E12: 3 | F12: 2 | G12: 2 | H12: Havalı | I12: hg-antoryum-cicegi-topragi | J12: =IF(I12="","",IFERROR(INDEX(Topraklar!$B$2:$B$55,MATCH(I12,Topraklar!$A$2:$A$55,0)),"⚠ slug bulunamadı")) | K12: =INDEX(Uyum!$B$2:$AY$2,MATCH(MAX(Uyum!$B$13:$AY$13),Uyum!$B$13:$AY$13,0)) | L12: =MIN(1,MAX(Uyum!$B$13:$AY$13)) | M12: =IF(I12<>"",J12,K12) | N12: =IFERROR(TRIM(IF(E12>INDEX(Topraklar!$E$2:$E$55,MATCH(IF(I12<>"",I12,INDEX(Uyum!$B$1:$AY$1,MATCH(MAX(Uyum!$B$13:$AY$13),Uyum!$B$13:$AY$13,0))),Topraklar!$A$2:$A$55,0)),"Perlit karıştırın. ","")&IF(D12<INDEX(Topraklar!$D$2:$D$55,MATCH(IF(I12<>"",I12,INDEX(Uyum!$B$1:$AY$1,MATCH(MAX(Uyum!$B$13:$AY$13),Uyum!$B$13:$AY$13,0))),Topraklar!$A$2:$A$55,0)),"Asidik torf karıştırın. ","")&IF(F12>INDEX(Topraklar!$F$2:$F$55,MATCH(IF(I12<>"",I12,INDEX(Uyum!$B$1:$AY$1,MATCH(MAX(Uyum!$B$13:$AY$13),Uyum!$B$13:$AY$13,0))),Topraklar!$A$2:$A$55,0)),"Vermikülit karıştırın. ","")&IF(G12>INDEX(Topraklar!$G$2:$G$55,MATCH(IF(I12<>"",I12,INDEX(Uyum!$B$1:$AY$1,MATCH(MAX(Uyum!$B$13:$AY$13),Uyum!$B$13:$AY$13,0))),Topraklar!$A$2:$A$55,0)),"Solucan gübresi ekleyin.","")),"")
A13: Dua çiçeği | B13: maranta | C13: Salon | D13: 2 | E13: 2 | F13: 3 | G13: 2 | H13: Havalı | I13: hg-dua-cicegi-saksi-topragi | J13: =IF(I13="","",IFERROR(INDEX(Topraklar!$B$2:$B$55,MATCH(I13,Topraklar!$A$2:$A$55,0)),"⚠ slug bulunamadı")) | K13: =INDEX(Uyum!$B$2:$AY$2,MATCH(MAX(Uyum!$B$14:$AY$14),Uyum!$B$14:$AY$14,0)) | L13: =MIN(1,MAX(Uyum!$B$14:$AY$14)) | M13: =IF(I13<>"",J13,K13) | N13: =IFERROR(TRIM(IF(E13>INDEX(Topraklar!$E$2:$E$55,MATCH(IF(I13<>"",I13,INDEX(Uyum!$B$1:$AY$1,MATCH(MAX(Uyum!$B$14:$AY$14),Uyum!$B$14:$AY$14,0))),Topraklar!$A$2:$A$55,0)),"Perlit karıştırın. ","")&IF(D13<INDEX(Topraklar!$D$2:$D$55,MATCH(IF(I13<>"",I13,INDEX(Uyum!$B$1:$AY$1,MATCH(MAX(Uyum!$B$14:$AY$14),Uyum!$B$14:$AY$14,0))),Topraklar!$A$2:$A$55,0)),"Asidik torf karıştırın. ","")&IF(F13>INDEX(Topraklar!$F$2:$F$55,MATCH(IF(I13<>"",I13,INDEX(Uyum!$B$1:$AY$1,MATCH(MAX(Uyum!$B$14:$AY$14),Uyum!$B$14:$AY$14,0))),Topraklar!$A$2:$A$55,0)),"Vermikülit karıştırın. ","")&IF(G13>INDEX(Topraklar!$G$2:$G$55,MATCH(IF(I13<>"",I13,INDEX(Uyum!$B$1:$AY$1,MATCH(MAX(Uyum!$B$14:$AY$14),Uyum!$B$14:$AY$14,0))),Topraklar!$A$2:$A$55,0)),"Solucan gübresi ekleyin.","")),"")
A14: Calathea | B14: kalatea | C14: Salon | D14: 2 | E14: 2 | F14: 3 | G14: 2 | H14: Havalı | J14: =IF(I14="","",IFERROR(INDEX(Topraklar!$B$2:$B$55,MATCH(I14,Topraklar!$A$2:$A$55,0)),"⚠ slug bulunamadı")) | K14: =INDEX(Uyum!$B$2:$AY$2,MATCH(MAX(Uyum!$B$15:$AY$15),Uyum!$B$15:$AY$15,0)) | L14: =MIN(1,MAX(Uyum!$B$15:$AY$15)) | M14: =IF(I14<>"",J14,K14) | N14: =IFERROR(TRIM(IF(E14>INDEX(Topraklar!$E$2:$E$55,MATCH(IF(I14<>"",I14,INDEX(Uyum!$B$1:$AY$1,MATCH(MAX(Uyum!$B$15:$AY$15),Uyum!$B$15:$AY$15,0))),Topraklar!$A$2:$A$55,0)),"Perlit karıştırın. ","")&IF(D14<INDEX(Topraklar!$D$2:$D$55,MATCH(IF(I14<>"",I14,INDEX(Uyum!$B$1:$AY$1,MATCH(MAX(Uyum!$B$15:$AY$15),Uyum!$B$15:$AY$15,0))),Topraklar!$A$2:$A$55,0)),"Asidik torf karıştırın. ","")&IF(F14>INDEX(Topraklar!$F$2:$F$55,MATCH(IF(I14<>"",I14,INDEX(Uyum!$B$1:$AY$1,MATCH(MAX(Uyum!$B$15:$AY$15),Uyum!$B$15:$AY$15,0))),Topraklar!$A$2:$A$55,0)),"Vermikülit karıştırın. ","")&IF(G14>INDEX(Topraklar!$G$2:$G$55,MATCH(IF(I14<>"",I14,INDEX(Uyum!$B$1:$AY$1,MATCH(MAX(Uyum!$B$15:$AY$15),Uyum!$B$15:$AY$15,0))),Topraklar!$A$2:$A$55,0)),"Solucan gübresi ekleyin.","")),"")
A15: Fil kulağı | B15: alocasia, alokazya | C15: Salon | D15: 2 | E15: 2 | F15: 3 | G15: 3 | H15: Havalı | I15: hg-fil-kulagi-topragi | J15: =IF(I15="","",IFERROR(INDEX(Topraklar!$B$2:$B$55,MATCH(I15,Topraklar!$A$2:$A$55,0)),"⚠ slug bulunamadı")) | K15: =INDEX(Uyum!$B$2:$AY$2,MATCH(MAX(Uyum!$B$16:$AY$16),Uyum!$B$16:$AY$16,0)) | L15: =MIN(1,MAX(Uyum!$B$16:$AY$16)) | M15: =IF(I15<>"",J15,K15) | N15: =IFERROR(TRIM(IF(E15>INDEX(Topraklar!$E$2:$E$55,MATCH(IF(I15<>"",I15,INDEX(Uyum!$B$1:$AY$1,MATCH(MAX(Uyum!$B$16:$AY$16),Uyum!$B$16:$AY$16,0))),Topraklar!$A$2:$A$55,0)),"Perlit karıştırın. ","")&IF(D15<INDEX(Topraklar!$D$2:$D$55,MATCH(IF(I15<>"",I15,INDEX(Uyum!$B$1:$AY$1,MATCH(MAX(Uyum!$B$16:$AY$16),Uyum!$B$16:$AY$16,0))),Topraklar!$A$2:$A$55,0)),"Asidik torf karıştırın. ","")&IF(F15>INDEX(Topraklar!$F$2:$F$55,MATCH(IF(I15<>"",I15,INDEX(Uyum!$B$1:$AY$1,MATCH(MAX(Uyum!$B$16:$AY$16),Uyum!$B$16:$AY$16,0))),Topraklar!$A$2:$A$55,0)),"Vermikülit karıştırın. ","")&IF(G15>INDEX(Topraklar!$G$2:$G$55,MATCH(IF(I15<>"",I15,INDEX(Uyum!$B$1:$AY$1,MATCH(MAX(Uyum!$B$16:$AY$16),Uyum!$B$16:$AY$16,0))),Topraklar!$A$2:$A$55,0)),"Solucan gübresi ekleyin.","")),"")
A16: Areka palmiyesi | B16: areka, dypsis | C16: Salon | D16: 2 | E16: 2 | F16: 2 | G16: 2 | H16: Havalı | I16: areka-palmiyesi-topragi | J16: =IF(I16="","",IFERROR(INDEX(Topraklar!$B$2:$B$55,MATCH(I16,Topraklar!$A$2:$A$55,0)),"⚠ slug bulunamadı")) | K16: =INDEX(Uyum!$B$2:$AY$2,MATCH(MAX(Uyum!$B$17:$AY$17),Uyum!$B$17:$AY$17,0)) | L16: =MIN(1,MAX(Uyum!$B$17:$AY$17)) | M16: =IF(I16<>"",J16,K16) | N16: =IFERROR(TRIM(IF(E16>INDEX(Topraklar!$E$2:$E$55,MATCH(IF(I16<>"",I16,INDEX(Uyum!$B$1:$AY$1,MATCH(MAX(Uyum!$B$17:$AY$17),Uyum!$B$17:$AY$17,0))),Topraklar!$A$2:$A$55,0)),"Perlit karıştırın. ","")&IF(D16<INDEX(Topraklar!$D$2:$D$55,MATCH(IF(I16<>"",I16,INDEX(Uyum!$B$1:$AY$1,MATCH(MAX(Uyum!$B$17:$AY$17),Uyum!$B$17:$AY$17,0))),Topraklar!$A$2:$A$55,0)),"Asidik torf karıştırın. ","")&IF(F16>INDEX(Topraklar!$F$2:$F$55,MATCH(IF(I16<>"",I16,INDEX(Uyum!$B$1:$AY$1,MATCH(MAX(Uyum!$B$17:$AY$17),Uyum!$B$17:$AY$17,0))),Topraklar!$A$2:$A$55,0)),"Vermikülit karıştırın. ","")&IF(G16>INDEX(Topraklar!$G$2:$G$55,MATCH(IF(I16<>"",I16,INDEX(Uyum!$B$1:$AY$1,MATCH(MAX(Uyum!$B$17:$AY$17),Uyum!$B$17:$AY$17,0))),Topraklar!$A$2:$A$55,0)),"Solucan gübresi ekleyin.","")),"")
A17: Kentia palmiyesi | B17: kentia, howea | C17: Salon | D17: 2 | E17: 2 | F17: 2 | G17: 2 | H17: Havalı | J17: =IF(I17="","",IFERROR(INDEX(Topraklar!$B$2:$B$55,MATCH(I17,Topraklar!$A$2:$A$55,0)),"⚠ slug bulunamadı")) | K17: =INDEX(Uyum!$B$2:$AY$2,MATCH(MAX(Uyum!$B$18:$AY$18),Uyum!$B$18:$AY$18,0)) | L17: =MIN(1,MAX(Uyum!$B$18:$AY$18)) | M17: =IF(I17<>"",J17,K17) | N17: =IFERROR(TRIM(IF(E17>INDEX(Topraklar!$E$2:$E$55,MATCH(IF(I17<>"",I17,INDEX(Uyum!$B$1:$AY$1,MATCH(MAX(Uyum!$B$18:$AY$18),Uyum!$B$18:$AY$18,0))),Topraklar!$A$2:$A$55,0)),"Perlit karıştırın. ","")&IF(D17<INDEX(Topraklar!$D$2:$D$55,MATCH(IF(I17<>"",I17,INDEX(Uyum!$B$1:$AY$1,MATCH(MAX(Uyum!$B$18:$AY$18),Uyum!$B$18:$AY$18,0))),Topraklar!$A$2:$A$55,0)),"Asidik torf karıştırın. ","")&IF(F17>INDEX(Topraklar!$F$2:$F$55,MATCH(IF(I17<>"",I17,INDEX(Uyum!$B$1:$AY$1,MATCH(MAX(Uyum!$B$18:$AY$18),Uyum!$B$18:$AY$18,0))),Topraklar!$A$2:$A$55,0)),"Vermikülit karıştırın. ","")&IF(G17>INDEX(Topraklar!$G$2:$G$55,MATCH(IF(I17<>"",I17,INDEX(Uyum!$B$1:$AY$1,MATCH(MAX(Uyum!$B$18:$AY$18),Uyum!$B$18:$AY$18,0))),Topraklar!$A$2:$A$55,0)),"Solucan gübresi ekleyin.","")),"")
A18: Şeflera | B18: schefflera | C18: Salon | D18: 2 | E18: 2 | F18: 2 | G18: 2 | H18: Dengeli | I18: hg-seflera-schefflera-topragi | J18: =IF(I18="","",IFERROR(INDEX(Topraklar!$B$2:$B$55,MATCH(I18,Topraklar!$A$2:$A$55,0)),"⚠ slug bulunamadı")) | K18: =INDEX(Uyum!$B$2:$AY$2,MATCH(MAX(Uyum!$B$19:$AY$19),Uyum!$B$19:$AY$19,0)) | L18: =MIN(1,MAX(Uyum!$B$19:$AY$19)) | M18: =IF(I18<>"",J18,K18) | N18: =IFERROR(TRIM(IF(E18>INDEX(Topraklar!$E$2:$E$55,MATCH(IF(I18<>"",I18,INDEX(Uyum!$B$1:$AY$1,MATCH(MAX(Uyum!$B$19:$AY$19),Uyum!$B$19:$AY$19,0))),Topraklar!$A$2:$A$55,0)),"Perlit karıştırın. ","")&IF(D18<INDEX(Topraklar!$D$2:$D$55,MATCH(IF(I18<>"",I18,INDEX(Uyum!$B$1:$AY$1,MATCH(MAX(Uyum!$B$19:$AY$19),Uyum!$B$19:$AY$19,0))),Topraklar!$A$2:$A$55,0)),"Asidik torf karıştırın. ","")&IF(F18>INDEX(Topraklar!$F$2:$F$55,MATCH(IF(I18<>"",I18,INDEX(Uyum!$B$1:$AY$1,MATCH(MAX(Uyum!$B$19:$AY$19),Uyum!$B$19:$AY$19,0))),Topraklar!$A$2:$A$55,0)),"Vermikülit karıştırın. ","")&IF(G18>INDEX(Topraklar!$G$2:$G$55,MATCH(IF(I18<>"",I18,INDEX(Uyum!$B$1:$AY$1,MATCH(MAX(Uyum!$B$19:$AY$19),Uyum!$B$19:$AY$19,0))),Topraklar!$A$2:$A$55,0)),"Solucan gübresi ekleyin.","")),"")
A19: Pilea | B19: çin para çiçeği | C19: Salon | D19: 2 | E19: 2 | F19: 2 | G19: 2 | H19: Havalı | I19: hg-cin-para-cicegi-pilea-saksi-topragi | J19: =IF(I19="","",IFERROR(INDEX(Topraklar!$B$2:$B$55,MATCH(I19,Topraklar!$A$2:$A$55,0)),"⚠ slug bulunamadı")) | K19: =INDEX(Uyum!$B$2:$AY$2,MATCH(MAX(Uyum!$B$20:$AY$20),Uyum!$B$20:$AY$20,0)) | L19: =MIN(1,MAX(Uyum!$B$20:$AY$20)) | M19: =IF(I19<>"",J19,K19) | N19: =IFERROR(TRIM(IF(E19>INDEX(Topraklar!$E$2:$E$55,MATCH(IF(I19<>"",I19,INDEX(Uyum!$B$1:$AY$1,MATCH(MAX(Uyum!$B$20:$AY$20),Uyum!$B$20:$AY$20,0))),Topraklar!$A$2:$A$55,0)),"Perlit karıştırın. ","")&IF(D19<INDEX(Topraklar!$D$2:$D$55,MATCH(IF(I19<>"",I19,INDEX(Uyum!$B$1:$AY$1,MATCH(MAX(Uyum!$B$20:$AY$20),Uyum!$B$20:$AY$20,0))),Topraklar!$A$2:$A$55,0)),"Asidik torf karıştırın. ","")&IF(F19>INDEX(Topraklar!$F$2:$F$55,MATCH(IF(I19<>"",I19,INDEX(Uyum!$B$1:$AY$1,MATCH(MAX(Uyum!$B$20:$AY$20),Uyum!$B$20:$AY$20,0))),Topraklar!$A$2:$A$55,0)),"Vermikülit karıştırın. ","")&IF(G19>INDEX(Topraklar!$G$2:$G$55,MATCH(IF(I19<>"",I19,INDEX(Uyum!$B$1:$AY$1,MATCH(MAX(Uyum!$B$20:$AY$20),Uyum!$B$20:$AY$20,0))),Topraklar!$A$2:$A$55,0)),"Solucan gübresi ekleyin.","")),"")
A20: Dracaena | B20: ejderha ağacı, drasena | C20: Salon | D20: 2 | E20: 2 | F20: 2 | G20: 2 | H20: Dengeli | J20: =IF(I20="","",IFERROR(INDEX(Topraklar!$B$2:$B$55,MATCH(I20,Topraklar!$A$2:$A$55,0)),"⚠ slug bulunamadı")) | K20: =INDEX(Uyum!$B$2:$AY$2,MATCH(MAX(Uyum!$B$21:$AY$21),Uyum!$B$21:$AY$21,0)) | L20: =MIN(1,MAX(Uyum!$B$21:$AY$21)) | M20: =IF(I20<>"",J20,K20) | N20: =IFERROR(TRIM(IF(E20>INDEX(Topraklar!$E$2:$E$55,MATCH(IF(I20<>"",I20,INDEX(Uyum!$B$1:$AY$1,MATCH(MAX(Uyum!$B$21:$AY$21),Uyum!$B$21:$AY$21,0))),Topraklar!$A$2:$A$55,0)),"Perlit karıştırın. ","")&IF(D20<INDEX(Topraklar!$D$2:$D$55,MATCH(IF(I20<>"",I20,INDEX(Uyum!$B$1:$AY$1,MATCH(MAX(Uyum!$B$21:$AY$21),Uyum!$B$21:$AY$21,0))),Topraklar!$A$2:$A$55,0)),"Asidik torf karıştırın. ","")&IF(F20>INDEX(Topraklar!$F$2:$F$55,MATCH(IF(I20<>"",I20,INDEX(Uyum!$B$1:$AY$1,MATCH(MAX(Uyum!$B$21:$AY$21),Uyum!$B$21:$AY$21,0))),Topraklar!$A$2:$A$55,0)),"Vermikülit karıştırın. ","")&IF(G20>INDEX(Topraklar!$G$2:$G$55,MATCH(IF(I20<>"",I20,INDEX(Uyum!$B$1:$AY$1,MATCH(MAX(Uyum!$B$21:$AY$21),Uyum!$B$21:$AY$21,0))),Topraklar!$A$2:$A$55,0)),"Solucan gübresi ekleyin.","")),"")
A21: Aglaonema | B21: çin her dem yeşili | C21: Salon | D21: 2 | E21: 2 | F21: 2 | G21: 2 | H21: Havalı | J21: =IF(I21="","",IFERROR(INDEX(Topraklar!$B$2:$B$55,MATCH(I21,Topraklar!$A$2:$A$55,0)),"⚠ slug bulunamadı")) | K21: =INDEX(Uyum!$B$2:$AY$2,MATCH(MAX(Uyum!$B$22:$AY$22),Uyum!$B$22:$AY$22,0)) | L21: =MIN(1,MAX(Uyum!$B$22:$AY$22)) | M21: =IF(I21<>"",J21,K21) | N21: =IFERROR(TRIM(IF(E21>INDEX(Topraklar!$E$2:$E$55,MATCH(IF(I21<>"",I21,INDEX(Uyum!$B$1:$AY$1,MATCH(MAX(Uyum!$B$22:$AY$22),Uyum!$B$22:$AY$22,0))),Topraklar!$A$2:$A$55,0)),"Perlit karıştırın. ","")&IF(D21<INDEX(Topraklar!$D$2:$D$55,MATCH(IF(I21<>"",I21,INDEX(Uyum!$B$1:$AY$1,MATCH(MAX(Uyum!$B$22:$AY$22),Uyum!$B$22:$AY$22,0))),Topraklar!$A$2:$A$55,0)),"Asidik torf karıştırın. ","")&IF(F21>INDEX(Topraklar!$F$2:$F$55,MATCH(IF(I21<>"",I21,INDEX(Uyum!$B$1:$AY$1,MATCH(MAX(Uyum!$B$22:$AY$22),Uyum!$B$22:$AY$22,0))),Topraklar!$A$2:$A$55,0)),"Vermikülit karıştırın. ","")&IF(G21>INDEX(Topraklar!$G$2:$G$55,MATCH(IF(I21<>"",I21,INDEX(Uyum!$B$1:$AY$1,MATCH(MAX(Uyum!$B$22:$AY$22),Uyum!$B$22:$AY$22,0))),Topraklar!$A$2:$A$55,0)),"Solucan gübresi ekleyin.","")),"")
A22: Kurdele çiçeği | B22: chlorophytum, örümcek bitkisi | C22: Salon | D22: 2 | E22: 2 | F22: 2 | G22: 2 | H22: Dengeli | J22: =IF(I22="","",IFERROR(INDEX(Topraklar!$B$2:$B$55,MATCH(I22,Topraklar!$A$2:$A$55,0)),"⚠ slug bulunamadı")) | K22: =INDEX(Uyum!$B$2:$AY$2,MATCH(MAX(Uyum!$B$23:$AY$23),Uyum!$B$23:$AY$23,0)) | L22: =MIN(1,MAX(Uyum!$B$23:$AY$23)) | M22: =IF(I22<>"",J22,K22) | N22: =IFERROR(TRIM(IF(E22>INDEX(Topraklar!$E$2:$E$55,MATCH(IF(I22<>"",I22,INDEX(Uyum!$B$1:$AY$1,MATCH(MAX(Uyum!$B$23:$AY$23),Uyum!$B$23:$AY$23,0))),Topraklar!$A$2:$A$55,0)),"Perlit karıştırın. ","")&IF(D22<INDEX(Topraklar!$D$2:$D$55,MATCH(IF(I22<>"",I22,INDEX(Uyum!$B$1:$AY$1,MATCH(MAX(Uyum!$B$23:$AY$23),Uyum!$B$23:$AY$23,0))),Topraklar!$A$2:$A$55,0)),"Asidik torf karıştırın. ","")&IF(F22>INDEX(Topraklar!$F$2:$F$55,MATCH(IF(I22<>"",I22,INDEX(Uyum!$B$1:$AY$1,MATCH(MAX(Uyum!$B$23:$AY$23),Uyum!$B$23:$AY$23,0))),Topraklar!$A$2:$A$55,0)),"Vermikülit karıştırın. ","")&IF(G22>INDEX(Topraklar!$G$2:$G$55,MATCH(IF(I22<>"",I22,INDEX(Uyum!$B$1:$AY$1,MATCH(MAX(Uyum!$B$23:$AY$23),Uyum!$B$23:$AY$23,0))),Topraklar!$A$2:$A$55,0)),"Solucan gübresi ekleyin.","")),"")
A23: Eğrelti otu | B23: fern, nephrolepis | C23: Salon | D23: 2 | E23: 2 | F23: 3 | G23: 2 | H23: Havalı | J23: =IF(I23="","",IFERROR(INDEX(Topraklar!$B$2:$B$55,MATCH(I23,Topraklar!$A$2:$A$55,0)),"⚠ slug bulunamadı")) | K23: =INDEX(Uyum!$B$2:$AY$2,MATCH(MAX(Uyum!$B$24:$AY$24),Uyum!$B$24:$AY$24,0)) | L23: =MIN(1,MAX(Uyum!$B$24:$AY$24)) | M23: =IF(I23<>"",J23,K23) | N23: =IFERROR(TRIM(IF(E23>INDEX(Topraklar!$E$2:$E$55,MATCH(IF(I23<>"",I23,INDEX(Uyum!$B$1:$AY$1,MATCH(MAX(Uyum!$B$24:$AY$24),Uyum!$B$24:$AY$24,0))),Topraklar!$A$2:$A$55,0)),"Perlit karıştırın. ","")&IF(D23<INDEX(Topraklar!$D$2:$D$55,MATCH(IF(I23<>"",I23,INDEX(Uyum!$B$1:$AY$1,MATCH(MAX(Uyum!$B$24:$AY$24),Uyum!$B$24:$AY$24,0))),Topraklar!$A$2:$A$55,0)),"Asidik torf karıştırın. ","")&IF(F23>INDEX(Topraklar!$F$2:$F$55,MATCH(IF(I23<>"",I23,INDEX(Uyum!$B$1:$AY$1,MATCH(MAX(Uyum!$B$24:$AY$24),Uyum!$B$24:$AY$24,0))),Topraklar!$A$2:$A$55,0)),"Vermikülit karıştırın. ","")&IF(G23>INDEX(Topraklar!$G$2:$G$55,MATCH(IF(I23<>"",I23,INDEX(Uyum!$B$1:$AY$1,MATCH(MAX(Uyum!$B$24:$AY$24),Uyum!$B$24:$AY$24,0))),Topraklar!$A$2:$A$55,0)),"Solucan gübresi ekleyin.","")),"")
A24: Guzmanya | B24: bromelya, guzmania | C24: Salon | D24: 2 | E24: 3 | F24: 1 | G24: 1 | H24: Havalı | J24: =IF(I24="","",IFERROR(INDEX(Topraklar!$B$2:$B$55,MATCH(I24,Topraklar!$A$2:$A$55,0)),"⚠ slug bulunamadı")) | K24: =INDEX(Uyum!$B$2:$AY$2,MATCH(MAX(Uyum!$B$25:$AY$25),Uyum!$B$25:$AY$25,0)) | L24: =MIN(1,MAX(Uyum!$B$25:$AY$25)) | M24: =IF(I24<>"",J24,K24) | N24: =IFERROR(TRIM(IF(E24>INDEX(Topraklar!$E$2:$E$55,MATCH(IF(I24<>"",I24,INDEX(Uyum!$B$1:$AY$1,MATCH(MAX(Uyum!$B$25:$AY$25),Uyum!$B$25:$AY$25,0))),Topraklar!$A$2:$A$55,0)),"Perlit karıştırın. ","")&IF(D24<INDEX(Topraklar!$D$2:$D$55,MATCH(IF(I24<>"",I24,INDEX(Uyum!$B$1:$AY$1,MATCH(MAX(Uyum!$B$25:$AY$25),Uyum!$B$25:$AY$25,0))),Topraklar!$A$2:$A$55,0)),"Asidik torf karıştırın. ","")&IF(F24>INDEX(Topraklar!$F$2:$F$55,MATCH(IF(I24<>"",I24,INDEX(Uyum!$B$1:$AY$1,MATCH(MAX(Uyum!$B$25:$AY$25),Uyum!$B$25:$AY$25,0))),Topraklar!$A$2:$A$55,0)),"Vermikülit karıştırın. ","")&IF(G24>INDEX(Topraklar!$G$2:$G$55,MATCH(IF(I24<>"",I24,INDEX(Uyum!$B$1:$AY$1,MATCH(MAX(Uyum!$B$25:$AY$25),Uyum!$B$25:$AY$25,0))),Topraklar!$A$2:$A$55,0)),"Solucan gübresi ekleyin.","")),"")
A25: Begonya | B25: begonia | C25: Salon | D25: 2 | E25: 2 | F25: 2 | G25: 2 | H25: Havalı | J25: =IF(I25="","",IFERROR(INDEX(Topraklar!$B$2:$B$55,MATCH(I25,Topraklar!$A$2:$A$55,0)),"⚠ slug bulunamadı")) | K25: =INDEX(Uyum!$B$2:$AY$2,MATCH(MAX(Uyum!$B$26:$AY$26),Uyum!$B$26:$AY$26,0)) | L25: =MIN(1,MAX(Uyum!$B$26:$AY$26)) | M25: =IF(I25<>"",J25,K25) | N25: =IFERROR(TRIM(IF(E25>INDEX(Topraklar!$E$2:$E$55,MATCH(IF(I25<>"",I25,INDEX(Uyum!$B$1:$AY$1,MATCH(MAX(Uyum!$B$26:$AY$26),Uyum!$B$26:$AY$26,0))),Topraklar!$A$2:$A$55,0)),"Perlit karıştırın. ","")&IF(D25<INDEX(Topraklar!$D$2:$D$55,MATCH(IF(I25<>"",I25,INDEX(Uyum!$B$1:$AY$1,MATCH(MAX(Uyum!$B$26:$AY$26),Uyum!$B$26:$AY$26,0))),Topraklar!$A$2:$A$55,0)),"Asidik torf karıştırın. ","")&IF(F25>INDEX(Topraklar!$F$2:$F$55,MATCH(IF(I25<>"",I25,INDEX(Uyum!$B$1:$AY$1,MATCH(MAX(Uyum!$B$26:$AY$26),Uyum!$B$26:$AY$26,0))),Topraklar!$A$2:$A$55,0)),"Vermikülit karıştırın. ","")&IF(G25>INDEX(Topraklar!$G$2:$G$55,MATCH(IF(I25<>"",I25,INDEX(Uyum!$B$1:$AY$1,MATCH(MAX(Uyum!$B$26:$AY$26),Uyum!$B$26:$AY$26,0))),Topraklar!$A$2:$A$55,0)),"Solucan gübresi ekleyin.","")),"")
A26: Atatürk çiçeği | B26: poinsettia, ponsetya | C26: Salon | D26: 2 | E26: 2 | F26: 2 | G26: 2 | H26: Dengeli | J26: =IF(I26="","",IFERROR(INDEX(Topraklar!$B$2:$B$55,MATCH(I26,Topraklar!$A$2:$A$55,0)),"⚠ slug bulunamadı")) | K26: =INDEX(Uyum!$B$2:$AY$2,MATCH(MAX(Uyum!$B$27:$AY$27),Uyum!$B$27:$AY$27,0)) | L26: =MIN(1,MAX(Uyum!$B$27:$AY$27)) | M26: =IF(I26<>"",J26,K26) | N26: =IFERROR(TRIM(IF(E26>INDEX(Topraklar!$E$2:$E$55,MATCH(IF(I26<>"",I26,INDEX(Uyum!$B$1:$AY$1,MATCH(MAX(Uyum!$B$27:$AY$27),Uyum!$B$27:$AY$27,0))),Topraklar!$A$2:$A$55,0)),"Perlit karıştırın. ","")&IF(D26<INDEX(Topraklar!$D$2:$D$55,MATCH(IF(I26<>"",I26,INDEX(Uyum!$B$1:$AY$1,MATCH(MAX(Uyum!$B$27:$AY$27),Uyum!$B$27:$AY$27,0))),Topraklar!$A$2:$A$55,0)),"Asidik torf karıştırın. ","")&IF(F26>INDEX(Topraklar!$F$2:$F$55,MATCH(IF(I26<>"",I26,INDEX(Uyum!$B$1:$AY$1,MATCH(MAX(Uyum!$B$27:$AY$27),Uyum!$B$27:$AY$27,0))),Topraklar!$A$2:$A$55,0)),"Vermikülit karıştırın. ","")&IF(G26>INDEX(Topraklar!$G$2:$G$55,MATCH(IF(I26<>"",I26,INDEX(Uyum!$B$1:$AY$1,MATCH(MAX(Uyum!$B$27:$AY$27),Uyum!$B$27:$AY$27,0))),Topraklar!$A$2:$A$55,0)),"Solucan gübresi ekleyin.","")),"")
A27: Yuka | B27: yucca | C27: Salon | D27: 3 | E27: 3 | F27: 1 | G27: 1 | H27: Kumlu | I27: yuka-yucca-topragi-ozel-karisim | J27: =IF(I27="","",IFERROR(INDEX(Topraklar!$B$2:$B$55,MATCH(I27,Topraklar!$A$2:$A$55,0)),"⚠ slug bulunamadı")) | K27: =INDEX(Uyum!$B$2:$AY$2,MATCH(MAX(Uyum!$B$28:$AY$28),Uyum!$B$28:$AY$28,0)) | L27: =MIN(1,MAX(Uyum!$B$28:$AY$28)) | M27: =IF(I27<>"",J27,K27) | N27: =IFERROR(TRIM(IF(E27>INDEX(Topraklar!$E$2:$E$55,MATCH(IF(I27<>"",I27,INDEX(Uyum!$B$1:$AY$1,MATCH(MAX(Uyum!$B$28:$AY$28),Uyum!$B$28:$AY$28,0))),Topraklar!$A$2:$A$55,0)),"Perlit karıştırın. ","")&IF(D27<INDEX(Topraklar!$D$2:$D$55,MATCH(IF(I27<>"",I27,INDEX(Uyum!$B$1:$AY$1,MATCH(MAX(Uyum!$B$28:$AY$28),Uyum!$B$28:$AY$28,0))),Topraklar!$A$2:$A$55,0)),"Asidik torf karıştırın. ","")&IF(F27>INDEX(Topraklar!$F$2:$F$55,MATCH(IF(I27<>"",I27,INDEX(Uyum!$B$1:$AY$1,MATCH(MAX(Uyum!$B$28:$AY$28),Uyum!$B$28:$AY$28,0))),Topraklar!$A$2:$A$55,0)),"Vermikülit karıştırın. ","")&IF(G27>INDEX(Topraklar!$G$2:$G$55,MATCH(IF(I27<>"",I27,INDEX(Uyum!$B$1:$AY$1,MATCH(MAX(Uyum!$B$28:$AY$28),Uyum!$B$28:$AY$28,0))),Topraklar!$A$2:$A$55,0)),"Solucan gübresi ekleyin.","")),"")
A28: Aloe vera | B28: aloe, sarısabır | C28: Sukulent | D28: 3 | E28: 3 | F28: 1 | G28: 1 | H28: Kumlu | I28: hg-aloe-vera-topragi | J28: =IF(I28="","",IFERROR(INDEX(Topraklar!$B$2:$B$55,MATCH(I28,Topraklar!$A$2:$A$55,0)),"⚠ slug bulunamadı")) | K28: =INDEX(Uyum!$B$2:$AY$2,MATCH(MAX(Uyum!$B$29:$AY$29),Uyum!$B$29:$AY$29,0)) | L28: =MIN(1,MAX(Uyum!$B$29:$AY$29)) | M28: =IF(I28<>"",J28,K28) | N28: =IFERROR(TRIM(IF(E28>INDEX(Topraklar!$E$2:$E$55,MATCH(IF(I28<>"",I28,INDEX(Uyum!$B$1:$AY$1,MATCH(MAX(Uyum!$B$29:$AY$29),Uyum!$B$29:$AY$29,0))),Topraklar!$A$2:$A$55,0)),"Perlit karıştırın. ","")&IF(D28<INDEX(Topraklar!$D$2:$D$55,MATCH(IF(I28<>"",I28,INDEX(Uyum!$B$1:$AY$1,MATCH(MAX(Uyum!$B$29:$AY$29),Uyum!$B$29:$AY$29,0))),Topraklar!$A$2:$A$55,0)),"Asidik torf karıştırın. ","")&IF(F28>INDEX(Topraklar!$F$2:$F$55,MATCH(IF(I28<>"",I28,INDEX(Uyum!$B$1:$AY$1,MATCH(MAX(Uyum!$B$29:$AY$29),Uyum!$B$29:$AY$29,0))),Topraklar!$A$2:$A$55,0)),"Vermikülit karıştırın. ","")&IF(G28>INDEX(Topraklar!$G$2:$G$55,MATCH(IF(I28<>"",I28,INDEX(Uyum!$B$1:$AY$1,MATCH(MAX(Uyum!$B$29:$AY$29),Uyum!$B$29:$AY$29,0))),Topraklar!$A$2:$A$55,0)),"Solucan gübresi ekleyin.","")),"")
A29: Kaktüs | B29: cactus | C29: Sukulent | D29: 3 | E29: 3 | F29: 1 | G29: 1 | H29: Kumlu | I29: kaktus-ve-sukulent-topragi | J29: =IF(I29="","",IFERROR(INDEX(Topraklar!$B$2:$B$55,MATCH(I29,Topraklar!$A$2:$A$55,0)),"⚠ slug bulunamadı")) | K29: =INDEX(Uyum!$B$2:$AY$2,MATCH(MAX(Uyum!$B$30:$AY$30),Uyum!$B$30:$AY$30,0)) | L29: =MIN(1,MAX(Uyum!$B$30:$AY$30)) | M29: =IF(I29<>"",J29,K29) | N29: =IFERROR(TRIM(IF(E29>INDEX(Topraklar!$E$2:$E$55,MATCH(IF(I29<>"",I29,INDEX(Uyum!$B$1:$AY$1,MATCH(MAX(Uyum!$B$30:$AY$30),Uyum!$B$30:$AY$30,0))),Topraklar!$A$2:$A$55,0)),"Perlit karıştırın. ","")&IF(D29<INDEX(Topraklar!$D$2:$D$55,MATCH(IF(I29<>"",I29,INDEX(Uyum!$B$1:$AY$1,MATCH(MAX(Uyum!$B$30:$AY$30),Uyum!$B$30:$AY$30,0))),Topraklar!$A$2:$A$55,0)),"Asidik torf karıştırın. ","")&IF(F29>INDEX(Topraklar!$F$2:$F$55,MATCH(IF(I29<>"",I29,INDEX(Uyum!$B$1:$AY$1,MATCH(MAX(Uyum!$B$30:$AY$30),Uyum!$B$30:$AY$30,0))),Topraklar!$A$2:$A$55,0)),"Vermikülit karıştırın. ","")&IF(G29>INDEX(Topraklar!$G$2:$G$55,MATCH(IF(I29<>"",I29,INDEX(Uyum!$B$1:$AY$1,MATCH(MAX(Uyum!$B$30:$AY$30),Uyum!$B$30:$AY$30,0))),Topraklar!$A$2:$A$55,0)),"Solucan gübresi ekleyin.","")),"")
A30: Sukulent | B30: succulent, etli yapraklı | C30: Sukulent | D30: 3 | E30: 3 | F30: 1 | G30: 1 | H30: Kumlu | I30: kaktus-ve-sukulent-topragi | J30: =IF(I30="","",IFERROR(INDEX(Topraklar!$B$2:$B$55,MATCH(I30,Topraklar!$A$2:$A$55,0)),"⚠ slug bulunamadı")) | K30: =INDEX(Uyum!$B$2:$AY$2,MATCH(MAX(Uyum!$B$31:$AY$31),Uyum!$B$31:$AY$31,0)) | L30: =MIN(1,MAX(Uyum!$B$31:$AY$31)) | M30: =IF(I30<>"",J30,K30) | N30: =IFERROR(TRIM(IF(E30>INDEX(Topraklar!$E$2:$E$55,MATCH(IF(I30<>"",I30,INDEX(Uyum!$B$1:$AY$1,MATCH(MAX(Uyum!$B$31:$AY$31),Uyum!$B$31:$AY$31,0))),Topraklar!$A$2:$A$55,0)),"Perlit karıştırın. ","")&IF(D30<INDEX(Topraklar!$D$2:$D$55,MATCH(IF(I30<>"",I30,INDEX(Uyum!$B$1:$AY$1,MATCH(MAX(Uyum!$B$31:$AY$31),Uyum!$B$31:$AY$31,0))),Topraklar!$A$2:$A$55,0)),"Asidik torf karıştırın. ","")&IF(F30>INDEX(Topraklar!$F$2:$F$55,MATCH(IF(I30<>"",I30,INDEX(Uyum!$B$1:$AY$1,MATCH(MAX(Uyum!$B$31:$AY$31),Uyum!$B$31:$AY$31,0))),Topraklar!$A$2:$A$55,0)),"Vermikülit karıştırın. ","")&IF(G30>INDEX(Topraklar!$G$2:$G$55,MATCH(IF(I30<>"",I30,INDEX(Uyum!$B$1:$AY$1,MATCH(MAX(Uyum!$B$31:$AY$31),Uyum!$B$31:$AY$31,0))),Topraklar!$A$2:$A$55,0)),"Solucan gübresi ekleyin.","")),"")
A31: Yeşim | B31: crassula, yeşim ağacı | C31: Sukulent | D31: 3 | E31: 3 | F31: 1 | G31: 1 | H31: Kumlu | J31: =IF(I31="","",IFERROR(INDEX(Topraklar!$B$2:$B$55,MATCH(I31,Topraklar!$A$2:$A$55,0)),"⚠ slug bulunamadı")) | K31: =INDEX(Uyum!$B$2:$AY$2,MATCH(MAX(Uyum!$B$32:$AY$32),Uyum!$B$32:$AY$32,0)) | L31: =MIN(1,MAX(Uyum!$B$32:$AY$32)) | M31: =IF(I31<>"",J31,K31) | N31: =IFERROR(TRIM(IF(E31>INDEX(Topraklar!$E$2:$E$55,MATCH(IF(I31<>"",I31,INDEX(Uyum!$B$1:$AY$1,MATCH(MAX(Uyum!$B$32:$AY$32),Uyum!$B$32:$AY$32,0))),Topraklar!$A$2:$A$55,0)),"Perlit karıştırın. ","")&IF(D31<INDEX(Topraklar!$D$2:$D$55,MATCH(IF(I31<>"",I31,INDEX(Uyum!$B$1:$AY$1,MATCH(MAX(Uyum!$B$32:$AY$32),Uyum!$B$32:$AY$32,0))),Topraklar!$A$2:$A$55,0)),"Asidik torf karıştırın. ","")&IF(F31>INDEX(Topraklar!$F$2:$F$55,MATCH(IF(I31<>"",I31,INDEX(Uyum!$B$1:$AY$1,MATCH(MAX(Uyum!$B$32:$AY$32),Uyum!$B$32:$AY$32,0))),Topraklar!$A$2:$A$55,0)),"Vermikülit karıştırın. ","")&IF(G31>INDEX(Topraklar!$G$2:$G$55,MATCH(IF(I31<>"",I31,INDEX(Uyum!$B$1:$AY$1,MATCH(MAX(Uyum!$B$32:$AY$32),Uyum!$B$32:$AY$32,0))),Topraklar!$A$2:$A$55,0)),"Solucan gübresi ekleyin.","")),"")
A32: Kalanşo | B32: kalanchoe | C32: Sukulent | D32: 3 | E32: 3 | F32: 1 | G32: 2 | H32: Kumlu | J32: =IF(I32="","",IFERROR(INDEX(Topraklar!$B$2:$B$55,MATCH(I32,Topraklar!$A$2:$A$55,0)),"⚠ slug bulunamadı")) | K32: =INDEX(Uyum!$B$2:$AY$2,MATCH(MAX(Uyum!$B$33:$AY$33),Uyum!$B$33:$AY$33,0)) | L32: =MIN(1,MAX(Uyum!$B$33:$AY$33)) | M32: =IF(I32<>"",J32,K32) | N32: =IFERROR(TRIM(IF(E32>INDEX(Topraklar!$E$2:$E$55,MATCH(IF(I32<>"",I32,INDEX(Uyum!$B$1:$AY$1,MATCH(MAX(Uyum!$B$33:$AY$33),Uyum!$B$33:$AY$33,0))),Topraklar!$A$2:$A$55,0)),"Perlit karıştırın. ","")&IF(D32<INDEX(Topraklar!$D$2:$D$55,MATCH(IF(I32<>"",I32,INDEX(Uyum!$B$1:$AY$1,MATCH(MAX(Uyum!$B$33:$AY$33),Uyum!$B$33:$AY$33,0))),Topraklar!$A$2:$A$55,0)),"Asidik torf karıştırın. ","")&IF(F32>INDEX(Topraklar!$F$2:$F$55,MATCH(IF(I32<>"",I32,INDEX(Uyum!$B$1:$AY$1,MATCH(MAX(Uyum!$B$33:$AY$33),Uyum!$B$33:$AY$33,0))),Topraklar!$A$2:$A$55,0)),"Vermikülit karıştırın. ","")&IF(G32>INDEX(Topraklar!$G$2:$G$55,MATCH(IF(I32<>"",I32,INDEX(Uyum!$B$1:$AY$1,MATCH(MAX(Uyum!$B$33:$AY$33),Uyum!$B$33:$AY$33,0))),Topraklar!$A$2:$A$55,0)),"Solucan gübresi ekleyin.","")),"")
A33: Orkide | B33: orchid, phalaenopsis | C33: Salon | D33: 2 | E33: 3 | F33: 1 | G33: 1 | H33: Havalı | I33: gartengold-orkide-topragi | J33: =IF(I33="","",IFERROR(INDEX(Topraklar!$B$2:$B$55,MATCH(I33,Topraklar!$A$2:$A$55,0)),"⚠ slug bulunamadı")) | K33: =INDEX(Uyum!$B$2:$AY$2,MATCH(MAX(Uyum!$B$34:$AY$34),Uyum!$B$34:$AY$34,0)) | L33: =MIN(1,MAX(Uyum!$B$34:$AY$34)) | M33: =IF(I33<>"",J33,K33) | N33: =IFERROR(TRIM(IF(E33>INDEX(Topraklar!$E$2:$E$55,MATCH(IF(I33<>"",I33,INDEX(Uyum!$B$1:$AY$1,MATCH(MAX(Uyum!$B$34:$AY$34),Uyum!$B$34:$AY$34,0))),Topraklar!$A$2:$A$55,0)),"Perlit karıştırın. ","")&IF(D33<INDEX(Topraklar!$D$2:$D$55,MATCH(IF(I33<>"",I33,INDEX(Uyum!$B$1:$AY$1,MATCH(MAX(Uyum!$B$34:$AY$34),Uyum!$B$34:$AY$34,0))),Topraklar!$A$2:$A$55,0)),"Asidik torf karıştırın. ","")&IF(F33>INDEX(Topraklar!$F$2:$F$55,MATCH(IF(I33<>"",I33,INDEX(Uyum!$B$1:$AY$1,MATCH(MAX(Uyum!$B$34:$AY$34),Uyum!$B$34:$AY$34,0))),Topraklar!$A$2:$A$55,0)),"Vermikülit karıştırın. ","")&IF(G33>INDEX(Topraklar!$G$2:$G$55,MATCH(IF(I33<>"",I33,INDEX(Uyum!$B$1:$AY$1,MATCH(MAX(Uyum!$B$34:$AY$34),Uyum!$B$34:$AY$34,0))),Topraklar!$A$2:$A$55,0)),"Solucan gübresi ekleyin.","")),"")
A34: Afrika menekşesi | B34: menekşe, saintpaulia | C34: Salon | D34: 2 | E34: 2 | F34: 2 | G34: 2 | H34: Havalı | I34: hg-menekse-topragi | J34: =IF(I34="","",IFERROR(INDEX(Topraklar!$B$2:$B$55,MATCH(I34,Topraklar!$A$2:$A$55,0)),"⚠ slug bulunamadı")) | K34: =INDEX(Uyum!$B$2:$AY$2,MATCH(MAX(Uyum!$B$35:$AY$35),Uyum!$B$35:$AY$35,0)) | L34: =MIN(1,MAX(Uyum!$B$35:$AY$35)) | M34: =IF(I34<>"",J34,K34) | N34: =IFERROR(TRIM(IF(E34>INDEX(Topraklar!$E$2:$E$55,MATCH(IF(I34<>"",I34,INDEX(Uyum!$B$1:$AY$1,MATCH(MAX(Uyum!$B$35:$AY$35),Uyum!$B$35:$AY$35,0))),Topraklar!$A$2:$A$55,0)),"Perlit karıştırın. ","")&IF(D34<INDEX(Topraklar!$D$2:$D$55,MATCH(IF(I34<>"",I34,INDEX(Uyum!$B$1:$AY$1,MATCH(MAX(Uyum!$B$35:$AY$35),Uyum!$B$35:$AY$35,0))),Topraklar!$A$2:$A$55,0)),"Asidik torf karıştırın. ","")&IF(F34>INDEX(Topraklar!$F$2:$F$55,MATCH(IF(I34<>"",I34,INDEX(Uyum!$B$1:$AY$1,MATCH(MAX(Uyum!$B$35:$AY$35),Uyum!$B$35:$AY$35,0))),Topraklar!$A$2:$A$55,0)),"Vermikülit karıştırın. ","")&IF(G34>INDEX(Topraklar!$G$2:$G$55,MATCH(IF(I34<>"",I34,INDEX(Uyum!$B$1:$AY$1,MATCH(MAX(Uyum!$B$35:$AY$35),Uyum!$B$35:$AY$35,0))),Topraklar!$A$2:$A$55,0)),"Solucan gübresi ekleyin.","")),"")
A35: Begonvil | B35: bougainvillea | C35: Çiçek | D35: 2 | E35: 3 | F35: 1 | G35: 2 | H35: Kumlu | I35: hg-begonvil-topragi | J35: =IF(I35="","",IFERROR(INDEX(Topraklar!$B$2:$B$55,MATCH(I35,Topraklar!$A$2:$A$55,0)),"⚠ slug bulunamadı")) | K35: =INDEX(Uyum!$B$2:$AY$2,MATCH(MAX(Uyum!$B$36:$AY$36),Uyum!$B$36:$AY$36,0)) | L35: =MIN(1,MAX(Uyum!$B$36:$AY$36)) | M35: =IF(I35<>"",J35,K35) | N35: =IFERROR(TRIM(IF(E35>INDEX(Topraklar!$E$2:$E$55,MATCH(IF(I35<>"",I35,INDEX(Uyum!$B$1:$AY$1,MATCH(MAX(Uyum!$B$36:$AY$36),Uyum!$B$36:$AY$36,0))),Topraklar!$A$2:$A$55,0)),"Perlit karıştırın. ","")&IF(D35<INDEX(Topraklar!$D$2:$D$55,MATCH(IF(I35<>"",I35,INDEX(Uyum!$B$1:$AY$1,MATCH(MAX(Uyum!$B$36:$AY$36),Uyum!$B$36:$AY$36,0))),Topraklar!$A$2:$A$55,0)),"Asidik torf karıştırın. ","")&IF(F35>INDEX(Topraklar!$F$2:$F$55,MATCH(IF(I35<>"",I35,INDEX(Uyum!$B$1:$AY$1,MATCH(MAX(Uyum!$B$36:$AY$36),Uyum!$B$36:$AY$36,0))),Topraklar!$A$2:$A$55,0)),"Vermikülit karıştırın. ","")&IF(G35>INDEX(Topraklar!$G$2:$G$55,MATCH(IF(I35<>"",I35,INDEX(Uyum!$B$1:$AY$1,MATCH(MAX(Uyum!$B$36:$AY$36),Uyum!$B$36:$AY$36,0))),Topraklar!$A$2:$A$55,0)),"Solucan gübresi ekleyin.","")),"")
A36: Sardunya | B36: pelargonium, itır | C36: Çiçek | D36: 3 | E36: 3 | F36: 1 | G36: 2 | H36: Kumlu | I36: sardunya-pelargonium-cicegi-topragi | J36: =IF(I36="","",IFERROR(INDEX(Topraklar!$B$2:$B$55,MATCH(I36,Topraklar!$A$2:$A$55,0)),"⚠ slug bulunamadı")) | K36: =INDEX(Uyum!$B$2:$AY$2,MATCH(MAX(Uyum!$B$37:$AY$37),Uyum!$B$37:$AY$37,0)) | L36: =MIN(1,MAX(Uyum!$B$37:$AY$37)) | M36: =IF(I36<>"",J36,K36) | N36: =IFERROR(TRIM(IF(E36>INDEX(Topraklar!$E$2:$E$55,MATCH(IF(I36<>"",I36,INDEX(Uyum!$B$1:$AY$1,MATCH(MAX(Uyum!$B$37:$AY$37),Uyum!$B$37:$AY$37,0))),Topraklar!$A$2:$A$55,0)),"Perlit karıştırın. ","")&IF(D36<INDEX(Topraklar!$D$2:$D$55,MATCH(IF(I36<>"",I36,INDEX(Uyum!$B$1:$AY$1,MATCH(MAX(Uyum!$B$37:$AY$37),Uyum!$B$37:$AY$37,0))),Topraklar!$A$2:$A$55,0)),"Asidik torf karıştırın. ","")&IF(F36>INDEX(Topraklar!$F$2:$F$55,MATCH(IF(I36<>"",I36,INDEX(Uyum!$B$1:$AY$1,MATCH(MAX(Uyum!$B$37:$AY$37),Uyum!$B$37:$AY$37,0))),Topraklar!$A$2:$A$55,0)),"Vermikülit karıştırın. ","")&IF(G36>INDEX(Topraklar!$G$2:$G$55,MATCH(IF(I36<>"",I36,INDEX(Uyum!$B$1:$AY$1,MATCH(MAX(Uyum!$B$37:$AY$37),Uyum!$B$37:$AY$37,0))),Topraklar!$A$2:$A$55,0)),"Solucan gübresi ekleyin.","")),"")
A37: Starliçe | B37: cennet kuşu, strelitzia | C37: Salon | D37: 2 | E37: 2 | F37: 2 | G37: 3 | H37: Dengeli | I37: hg-starlice-cennet-kusu-topragi | J37: =IF(I37="","",IFERROR(INDEX(Topraklar!$B$2:$B$55,MATCH(I37,Topraklar!$A$2:$A$55,0)),"⚠ slug bulunamadı")) | K37: =INDEX(Uyum!$B$2:$AY$2,MATCH(MAX(Uyum!$B$38:$AY$38),Uyum!$B$38:$AY$38,0)) | L37: =MIN(1,MAX(Uyum!$B$38:$AY$38)) | M37: =IF(I37<>"",J37,K37) | N37: =IFERROR(TRIM(IF(E37>INDEX(Topraklar!$E$2:$E$55,MATCH(IF(I37<>"",I37,INDEX(Uyum!$B$1:$AY$1,MATCH(MAX(Uyum!$B$38:$AY$38),Uyum!$B$38:$AY$38,0))),Topraklar!$A$2:$A$55,0)),"Perlit karıştırın. ","")&IF(D37<INDEX(Topraklar!$D$2:$D$55,MATCH(IF(I37<>"",I37,INDEX(Uyum!$B$1:$AY$1,MATCH(MAX(Uyum!$B$38:$AY$38),Uyum!$B$38:$AY$38,0))),Topraklar!$A$2:$A$55,0)),"Asidik torf karıştırın. ","")&IF(F37>INDEX(Topraklar!$F$2:$F$55,MATCH(IF(I37<>"",I37,INDEX(Uyum!$B$1:$AY$1,MATCH(MAX(Uyum!$B$38:$AY$38),Uyum!$B$38:$AY$38,0))),Topraklar!$A$2:$A$55,0)),"Vermikülit karıştırın. ","")&IF(G37>INDEX(Topraklar!$G$2:$G$55,MATCH(IF(I37<>"",I37,INDEX(Uyum!$B$1:$AY$1,MATCH(MAX(Uyum!$B$38:$AY$38),Uyum!$B$38:$AY$38,0))),Topraklar!$A$2:$A$55,0)),"Solucan gübresi ekleyin.","")),"")
A38: Bonsai | C38: Salon | D38: 2 | E38: 3 | F38: 1 | G38: 1 | H38: Kumlu | I38: hg-bonsai-saksi-topragi | J38: =IF(I38="","",IFERROR(INDEX(Topraklar!$B$2:$B$55,MATCH(I38,Topraklar!$A$2:$A$55,0)),"⚠ slug bulunamadı")) | K38: =INDEX(Uyum!$B$2:$AY$2,MATCH(MAX(Uyum!$B$39:$AY$39),Uyum!$B$39:$AY$39,0)) | L38: =MIN(1,MAX(Uyum!$B$39:$AY$39)) | M38: =IF(I38<>"",J38,K38) | N38: =IFERROR(TRIM(IF(E38>INDEX(Topraklar!$E$2:$E$55,MATCH(IF(I38<>"",I38,INDEX(Uyum!$B$1:$AY$1,MATCH(MAX(Uyum!$B$39:$AY$39),Uyum!$B$39:$AY$39,0))),Topraklar!$A$2:$A$55,0)),"Perlit karıştırın. ","")&IF(D38<INDEX(Topraklar!$D$2:$D$55,MATCH(IF(I38<>"",I38,INDEX(Uyum!$B$1:$AY$1,MATCH(MAX(Uyum!$B$39:$AY$39),Uyum!$B$39:$AY$39,0))),Topraklar!$A$2:$A$55,0)),"Asidik torf karıştırın. ","")&IF(F38>INDEX(Topraklar!$F$2:$F$55,MATCH(IF(I38<>"",I38,INDEX(Uyum!$B$1:$AY$1,MATCH(MAX(Uyum!$B$39:$AY$39),Uyum!$B$39:$AY$39,0))),Topraklar!$A$2:$A$55,0)),"Vermikülit karıştırın. ","")&IF(G38>INDEX(Topraklar!$G$2:$G$55,MATCH(IF(I38<>"",I38,INDEX(Uyum!$B$1:$AY$1,MATCH(MAX(Uyum!$B$39:$AY$39),Uyum!$B$39:$AY$39,0))),Topraklar!$A$2:$A$55,0)),"Solucan gübresi ekleyin.","")),"")
A39: Para ağacı | B39: pachira | C39: Salon | D39: 2 | E39: 3 | F39: 1 | G39: 2 | H39: Kumlu | I39: hg-para-agaci-saksi-topragi | J39: =IF(I39="","",IFERROR(INDEX(Topraklar!$B$2:$B$55,MATCH(I39,Topraklar!$A$2:$A$55,0)),"⚠ slug bulunamadı")) | K39: =INDEX(Uyum!$B$2:$AY$2,MATCH(MAX(Uyum!$B$40:$AY$40),Uyum!$B$40:$AY$40,0)) | L39: =MIN(1,MAX(Uyum!$B$40:$AY$40)) | M39: =IF(I39<>"",J39,K39) | N39: =IFERROR(TRIM(IF(E39>INDEX(Topraklar!$E$2:$E$55,MATCH(IF(I39<>"",I39,INDEX(Uyum!$B$1:$AY$1,MATCH(MAX(Uyum!$B$40:$AY$40),Uyum!$B$40:$AY$40,0))),Topraklar!$A$2:$A$55,0)),"Perlit karıştırın. ","")&IF(D39<INDEX(Topraklar!$D$2:$D$55,MATCH(IF(I39<>"",I39,INDEX(Uyum!$B$1:$AY$1,MATCH(MAX(Uyum!$B$40:$AY$40),Uyum!$B$40:$AY$40,0))),Topraklar!$A$2:$A$55,0)),"Asidik torf karıştırın. ","")&IF(F39>INDEX(Topraklar!$F$2:$F$55,MATCH(IF(I39<>"",I39,INDEX(Uyum!$B$1:$AY$1,MATCH(MAX(Uyum!$B$40:$AY$40),Uyum!$B$40:$AY$40,0))),Topraklar!$A$2:$A$55,0)),"Vermikülit karıştırın. ","")&IF(G39>INDEX(Topraklar!$G$2:$G$55,MATCH(IF(I39<>"",I39,INDEX(Uyum!$B$1:$AY$1,MATCH(MAX(Uyum!$B$40:$AY$40),Uyum!$B$40:$AY$40,0))),Topraklar!$A$2:$A$55,0)),"Solucan gübresi ekleyin.","")),"")
A40: Gül | B40: rose | C40: Çiçek | D40: 3 | E40: 2 | F40: 2 | G40: 3 | H40: Dengeli | I40: hg-gul-topragi-gullere-ozel-toprak-karisimi | J40: =IF(I40="","",IFERROR(INDEX(Topraklar!$B$2:$B$55,MATCH(I40,Topraklar!$A$2:$A$55,0)),"⚠ slug bulunamadı")) | K40: =INDEX(Uyum!$B$2:$AY$2,MATCH(MAX(Uyum!$B$41:$AY$41),Uyum!$B$41:$AY$41,0)) | L40: =MIN(1,MAX(Uyum!$B$41:$AY$41)) | M40: =IF(I40<>"",J40,K40) | N40: =IFERROR(TRIM(IF(E40>INDEX(Topraklar!$E$2:$E$55,MATCH(IF(I40<>"",I40,INDEX(Uyum!$B$1:$AY$1,MATCH(MAX(Uyum!$B$41:$AY$41),Uyum!$B$41:$AY$41,0))),Topraklar!$A$2:$A$55,0)),"Perlit karıştırın. ","")&IF(D40<INDEX(Topraklar!$D$2:$D$55,MATCH(IF(I40<>"",I40,INDEX(Uyum!$B$1:$AY$1,MATCH(MAX(Uyum!$B$41:$AY$41),Uyum!$B$41:$AY$41,0))),Topraklar!$A$2:$A$55,0)),"Asidik torf karıştırın. ","")&IF(F40>INDEX(Topraklar!$F$2:$F$55,MATCH(IF(I40<>"",I40,INDEX(Uyum!$B$1:$AY$1,MATCH(MAX(Uyum!$B$41:$AY$41),Uyum!$B$41:$AY$41,0))),Topraklar!$A$2:$A$55,0)),"Vermikülit karıştırın. ","")&IF(G40>INDEX(Topraklar!$G$2:$G$55,MATCH(IF(I40<>"",I40,INDEX(Uyum!$B$1:$AY$1,MATCH(MAX(Uyum!$B$41:$AY$41),Uyum!$B$41:$AY$41,0))),Topraklar!$A$2:$A$55,0)),"Solucan gübresi ekleyin.","")),"")
...

Sheet Uyum
A1: slug → | B1: =Topraklar!A2 | C1: =Topraklar!A3 | D1: =Topraklar!A4 | E1: =Topraklar!A5 | F1: =Topraklar!A6 | G1: =Topraklar!A7 | H1: =Topraklar!A8 | I1: =Topraklar!A9 | J1: =Topraklar!A10 | K1: =Topraklar!A11 | L1: =Topraklar!A12 | M1: =Topraklar!A13 | N1: =Topraklar!A14 | O1: =Topraklar!A15 | P1: =Topraklar!A16 | Q1: =Topraklar!A17 | R1: =Topraklar!A18 | S1: =Topraklar!A19 | T1: =Topraklar!A20 | U1: =Topraklar!A21 | V1: =Topraklar!A22 | W1: =Topraklar!A23 | X1: =Topraklar!A24 | Y1: =Topraklar!A25 | Z1: =Topraklar!A26 | AA1: =Topraklar!A27 | AB1: =Topraklar!A28 | AC1: =Topraklar!A29 | AD1: =Topraklar!A30 | AE1: =Topraklar!A31 | AF1: =Topraklar!A32 | AG1: =Topraklar!A33 | AH1: =Topraklar!A34 | AI1: =Topraklar!A35 | AJ1: =Topraklar!A36 | AK1: =Topraklar!A37 | AL1: =Topraklar!A38 | AM1: =Topraklar!A39 | AN1: =Topraklar!A40 | AO1: =Topraklar!A41 | AP1: =Topraklar!A42 | AQ1: =Topraklar!A43 | AR1: =Topraklar!A44 | AS1: =Topraklar!A45 | AT1: =Topraklar!A46 | AU1: =Topraklar!A47 | AV1: =Topraklar!A48 | AW1: =Topraklar!A49 | AX1: =Topraklar!A50 | AY1: =Topraklar!A51
A2: Bitki ↓ / Toprak → | B2: =Topraklar!B2 | C2: =Topraklar!B3 | D2: =Topraklar!B4 | E2: =Topraklar!B5 | F2: =Topraklar!B6 | G2: =Topraklar!B7 | H2: =Topraklar!B8 | I2: =Topraklar!B9 | J2: =Topraklar!B10 | K2: =Topraklar!B11 | L2: =Topraklar!B12 | M2: =Topraklar!B13 | N2: =Topraklar!B14 | O2: =Topraklar!B15 | P2: =Topraklar!B16 | Q2: =Topraklar!B17 | R2: =Topraklar!B18 | S2: =Topraklar!B19 | T2: =Topraklar!B20 | U2: =Topraklar!B21 | V2: =Topraklar!B22 | W2: =Topraklar!B23 | X2: =Topraklar!B24 | Y2: =Topraklar!B25 | Z2: =Topraklar!B26 | AA2: =Topraklar!B27 | AB2: =Topraklar!B28 | AC2: =Topraklar!B29 | AD2: =Topraklar!B30 | AE2: =Topraklar!B31 | AF2: =Topraklar!B32 | AG2: =Topraklar!B33 | AH2: =Topraklar!B34 | AI2: =Topraklar!B35 | AJ2: =Topraklar!B36 | AK2: =Topraklar!B37 | AL2: =Topraklar!B38 | AM2: =Topraklar!B39 | AN2: =Topraklar!B40 | AO2: =Topraklar!B41 | AP2: =Topraklar!B42 | AQ2: =Topraklar!B43 | AR2: =Topraklar!B44 | AS2: =Topraklar!B45 | AT2: =Topraklar!B46 | AU2: =Topraklar!B47 | AV2: =Topraklar!B48 | AW2: =Topraklar!B49 | AX2: =Topraklar!B50 | AY2: =Topraklar!B51
